2018-31-31 15:22:03 mytest.py[line:74] ERROR There is a error in this file
Traceback (most recent call last):
  File "D:/Users/dell/PycharmProjects/PY/log/mytest.py", line 69, in parse
    cursor.execute(sql, param)
  File "C:\Users\dell\AppData\Local\Programs\Python\Python36-32\lib\site-packages\pymysql\cursors.py", line 170, in execute
    result = self._query(query)
  File "C:\Users\dell\AppData\Local\Programs\Python\Python36-32\lib\site-packages\pymysql\cursors.py", line 328, in _query
    conn.query(q)
  File "C:\Users\dell\AppData\Local\Programs\Python\Python36-32\lib\site-packages\pymysql\connections.py", line 516, in query
    self._affected_rows = self._read_query_result(unbuffered=unbuffered)
  File "C:\Users\dell\AppData\Local\Programs\Python\Python36-32\lib\site-packages\pymysql\connections.py", line 727, in _read_query_result
    result.read()
  File "C:\Users\dell\AppData\Local\Programs\Python\Python36-32\lib\site-packages\pymysql\connections.py", line 1066, in read
    first_packet = self.connection._read_packet()
  File "C:\Users\dell\AppData\Local\Programs\Python\Python36-32\lib\site-packages\pymysql\connections.py", line 683, in _read_packet
    packet.check_error()
  File "C:\Users\dell\AppData\Local\Programs\Python\Python36-32\lib\site-packages\pymysql\protocol.py", line 220, in check_error
    err.raise_mysql_exception(self._data)
  File "C:\Users\dell\AppData\Local\Programs\Python\Python36-32\lib\site-packages\pymysql\err.py", line 109, in raise_mysql_exception
    raise errorclass(errno, errval)
pymysql.err.ProgrammingError: (1146, "Table 'flightradar24.tes' doesn't exist")
